<?xml version="1.0"?>
<robot xmlns:xacro="http://www.ros.org/wiki/xacro">

    <xacro:macro name="project_perry" params="parent prefix *origin">

        <joint name="base_joint" type="fixed">
            <xacro:insert_block name="origin"/>
            <parent link="${parent}"/>
            <child link="base_link"/>
        </joint>

        <!-- Generated using onshape-to-robot -->
        <!-- Link base_link -->
        <link name="base_link">
            <inertial>
                <origin xyz="0.0217032 0.00136097 0.0312387" rpy="0 0 0"/>
                <mass value="2.80632"/>
                <inertia ixx="0.01476" ixy="-0.000561383" ixz="-0.000585443" iyy="0.0231544" iyz="-3.788e-05" izz="0.034474"/>
            </inertial>
            <!-- Part base_link -->
            <visual>
                <origin xyz="0 0 0" rpy="0 -0 0"/>
                <geometry>
                    <mesh filename="package://umrt-project-perry-description/assets/base_link.stl"/>
                </geometry>
                <material name="base_link_material">
                    <color rgba="0.980392 0.713725 0.00392157 1"/>
                </material>
            </visual>
            <collision>
                <origin xyz="0 0 0" rpy="0 -0 0"/>
                <geometry>
                    <mesh filename="package://umrt-project-perry-description/assets/base_link.stl"/>
                </geometry>
            </collision>
        </link>
        <!-- Link platter_link -->
        <link name="platter_link">
            <inertial>
                <origin xyz="-0.00116951 0.0133071 -0.0287373" rpy="0 0 0"/>
                <mass value="1.63507"/>
                <inertia ixx="0.00858588" ixy="-0.000126724" ixz="2.05093e-05" iyy="0.00495962" iyz="0.0004789" izz="0.0112158"/>
            </inertial>
            <!-- Part platter_link -->
            <visual>
                <origin xyz="0 0 -0.0028575" rpy="3.14159 -0 0"/>
                <geometry>
                    <mesh filename="package://umrt-project-perry-description/assets/platter_link.stl"/>
                </geometry>
                <material name="platter_link_material">
                    <color rgba="0.615686 0.811765 0.929412 1"/>
                </material>
            </visual>
            <collision>
                <origin xyz="0 0 -0.0028575" rpy="3.14159 -0 0"/>
                <geometry>
                    <mesh filename="package://umrt-project-perry-description/assets/platter_link.stl"/>
                </geometry>
            </collision>
        </link>
        <!-- Link humerus_link -->
        <link name="humerus_link">
            <inertial>
                <origin xyz="0.164436 -0.00339071 0.00134625" rpy="0 0 0"/>
                <mass value="3.56011"/>
                <inertia ixx="0.0086411" ixy="0.00118596" ixz="0.000373814" iyy="0.0327497" iyz="-3.92663e-05" izz="0.0358039"/>
            </inertial>
            <!-- Part humerus_link -->
            <visual>
                <origin xyz="-2.77556e-17 1.14354e-20 0.00191351" rpy="9.49411e-16 -7.77156e-16 -1.05915e-13"/>
                <geometry>
                    <mesh filename="package://umrt-project-perry-description/assets/humerus_link.stl"/>
                </geometry>
                <material name="humerus_link_material">
                    <color rgba="0.972549 0.529412 0.00392157 1"/>
                </material>
            </visual>
            <collision>
                <origin xyz="-2.77556e-17 1.14354e-20 0.00191351" rpy="9.49411e-16 -7.77156e-16 -1.05915e-13"/>
                <geometry>
                    <mesh filename="package://umrt-project-perry-description/assets/humerus_link.stl"/>
                </geometry>
            </collision>
        </link>
        <!-- Link ulna_link -->
        <link name="ulna_link">
            <inertial>
                <origin xyz="0.110616 -0.00829019 -0.00355982" rpy="0 0 0"/>
                <mass value="1.99897"/>
                <inertia ixx="0.00735145" ixy="-0.00226329" ixz="-1.19432e-05" iyy="0.0554343" iyz="-1.89527e-06" izz="0.0532783"/>
            </inertial>
            <!-- Part ulna_link -->
            <visual>
                <origin xyz="2.77556e-17 0 -0.002683" rpy="3.14159 -2.49188e-14 1.20993e-13"/>
                <geometry>
                    <mesh filename="package://umrt-project-perry-description/assets/ulna_link.stl"/>
                </geometry>
                <material name="ulna_link_material">
                    <color rgba="0.231373 0.380392 0.705882 1"/>
                </material>
            </visual>
            <collision>
                <origin xyz="2.77556e-17 0 -0.002683" rpy="3.14159 -2.49188e-14 1.20993e-13"/>
                <geometry>
                    <mesh filename="package://umrt-project-perry-description/assets/ulna_link.stl"/>
                </geometry>
            </collision>
        </link>
        <!-- Link wrist_link -->
        <link name="wrist_link">
            <inertial>
                <origin xyz="0.013323 -1.73937e-05 -0.000499842" rpy="0 0 0"/>
                <mass value="0.114952"/>
                <inertia ixx="0.000208967" ixy="-4.73277e-10" ixz="2.80543e-10" iyy="0.000141142" iyz="8.43109e-07" izz="9.77216e-05"/>
            </inertial>
            <!-- Part wrist_link -->
            <visual>
                <origin xyz="5.55112e-17 1.11022e-16 -0.0005" rpy="2.5307e-14 2.59572e-14 -8.82627e-15"/>
                <geometry>
                    <mesh filename="package://umrt-project-perry-description/assets/wrist_link.stl"/>
                </geometry>
                <material name="wrist_link_material">
                    <color rgba="0.972549 0.529412 0.00392157 1"/>
                </material>
            </visual>
            <collision>
                <origin xyz="5.55112e-17 1.11022e-16 -0.0005" rpy="2.5307e-14 2.59572e-14 -8.82627e-15"/>
                <geometry>
                    <mesh filename="package://umrt-project-perry-description/assets/wrist_link.stl"/>
                </geometry>
            </collision>
        </link>
        <!-- Link gripper_interface -->
        <link name="gripper_interface">
            <inertial>
                <origin xyz="-1.91636e-19 -8.24791e-19 -0.00328593" rpy="0 0 0"/>
                <mass value="0.0230672"/>
                <inertia ixx="6.54736e-06" ixy="-2.18071e-20" ixz="1.96807e-35" iyy="6.54736e-06" iyz="3.93705e-21" izz="1.27521e-05"/>
            </inertial>
            <!-- Part gripper_interface -->
            <visual>
                <origin xyz="0 -3.25261e-19 -0.00145" rpy="-3.14159 -1.07048e-16 1.5708"/>
                <geometry>
                    <mesh filename="package://umrt-project-perry-description/assets/gripper_interface.stl"/>
                </geometry>
                <material name="gripper_interface_material">
                    <color rgba="0.498039 0.498039 0.498039 1"/>
                </material>
            </visual>
            <collision>
                <origin xyz="0 -3.25261e-19 -0.00145" rpy="-3.14159 -1.07048e-16 1.5708"/>
                <geometry>
                    <mesh filename="package://umrt-project-perry-description/assets/gripper_interface.stl"/>
                </geometry>
            </collision>
        </link>
        <!-- Joint from wrist_link to gripper_interface -->
        <joint name="wrist_roll" type="revolute">
            <origin xyz="0.0299983 -1.11022e-16 -0.0005" rpy="-1.5708 -2.5307e-14 1.5708"/>
            <parent link="wrist_link"/>
            <child link="gripper_interface"/>
            <axis xyz="0 0 1"/>
            <limit effort="10" velocity="10" lower="-3.141592653589793" upper="3.141592653589793"/>
        </joint>
        <!-- Joint from ulna_link to wrist_link -->
        <joint name="wrist_pitch" type="revolute">
            <origin xyz="0.3937 4.75175e-14 -0.00169862" rpy="-2.38638e-14 -2.49188e-14 1.20993e-13"/>
            <parent link="ulna_link"/>
            <child link="wrist_link"/>
            <axis xyz="0 0 1"/>
            <limit effort="10" velocity="10" lower="-1.5708" upper="1.5708"/>
        </joint>
        <!-- Joint from humerus_link to ulna_link -->
        <joint name="elbow_pitch" type="revolute">
            <origin xyz="0.4572 -0.031582 0.00354351" rpy="-7.77156e-16 -1.07188e-15 1.5708"/>
            <parent link="humerus_link"/>
            <child link="ulna_link"/>
            <axis xyz="0 0 1"/>
            <limit effort="10" velocity="10" lower="-0.959931" upper="0.610865"/>
        </joint>
        <!-- Joint from platter_link to humerus_link -->
        <joint name="base_pitch" type="revolute">
            <origin xyz="2.34735e-18 -0.0020731 -0.0879775" rpy="-1.5708 1.5708 0"/>
            <parent link="platter_link"/>
            <child link="humerus_link"/>
            <axis xyz="0 0 1"/>
            <limit effort="10" velocity="10" lower="-1.5708" upper="1.5708"/>
        </joint>
        <!-- Joint from base_link to platter_link -->
        <joint name="base_yaw" type="revolute">
            <origin xyz="0 0 0.0807747" rpy="3.14159 -0 0"/>
            <parent link="base_link"/>
            <child link="platter_link"/>
            <axis xyz="0 0 1"/>
            <limit effort="10" velocity="10" lower="-3.141592653589793" upper="3.141592653589793"/>
        </joint>

    </xacro:macro>

</robot>
