<?xml version="1.0"?>
<robot xmlns:xacro="http://www.ros.org/wiki/xacro">

    <xacro:macro name="project_perry" params="parent prefix *origin">

        <joint name="base_joint" type="fixed">
            <xacro:insert_block name="origin"/>
            <parent link="${parent}"/>
            <child link="base_link"/>
        </joint>

        <!-- Generated using onshape-to-robot -->
        <!-- Link base_link -->
        <link name="base_link">
            <inertial>
                <origin xyz="0.00286812 -0.0209097 0.0286943" rpy="0 0 0"/>
                <mass value="2.80632"/>
                <inertia ixx="0.0231691" ixy="0.00065571" ixz="-0.000230556" iyy="0.0147789" iyz="0.000656447" izz="0.0344912"/>
            </inertial>
            <!-- Part base_link_parts -->
            <visual>
                <origin xyz="0.00286812 -0.0209097 0.0286943" rpy="0 -0 0"/>
                <geometry>
                    <mesh filename="package://assets/merged/base_link_visual.stl"/>
                </geometry>
                <material name="base_link_parts_material">
                    <color rgba="0.0745098 0.678431 0.972549 1"/>
                </material>
            </visual>
            <collision>
                <origin xyz="0.00286812 -0.0209097 0.0286943" rpy="0 -0 0"/>
                <geometry>
                    <mesh filename="package://assets/merged/base_link_collision.stl"/>
                </geometry>
            </collision>
        </link>
        <!-- Link base_platter -->
        <link name="base_platter">
            <inertial>
                <origin xyz="-0.0119595 -0.00118557 -0.0231327" rpy="0 0 0"/>
                <mass value="1.84265"/>
                <inertia ixx="0.00590316" ixy="0.000138602" ixz="-0.000532603" iyy="0.00955076" iyz="2.11489e-05" izz="0.012905"/>
            </inertial>
            <!-- Part base_platter_parts -->
            <visual>
                <origin xyz="-0.0119595 -0.00118557 -0.0231327" rpy="-3.13855 -0.016189 0.947366"/>
                <geometry>
                    <mesh filename="package://assets/merged/base_platter_visual.stl"/>
                </geometry>
                <material name="base_platter_parts_material">
                    <color rgba="0.570634 0.573152 0.433741 1"/>
                </material>
            </visual>
            <collision>
                <origin xyz="-0.0119595 -0.00118557 -0.0231327" rpy="-3.13855 -0.016189 0.947366"/>
                <geometry>
                    <mesh filename="package://assets/merged/base_platter_collision.stl"/>
                </geometry>
            </collision>
        </link>
        <!-- Link humerus_link -->
        <link name="humerus_link">
            <inertial>
                <origin xyz="0.192899 1.61439e-05 -0.0214358" rpy="0 0 0"/>
                <mass value="2.10608"/>
                <inertia ixx="0.00597093" ixy="-0.00115128" ixz="-0.000267892" iyy="0.0356475" iyz="-2.43475e-05" izz="0.0374601"/>
            </inertial>
            <!-- Part humerus_link_parts -->
            <visual>
                <origin xyz="0.192899 1.61439e-05 -0.0214358" rpy="-1.5794 0.623336 -1.23434"/>
                <geometry>
                    <mesh filename="package://assets/merged/humerus_link_visual.stl"/>
                </geometry>
                <material name="humerus_link_parts_material">
                    <color rgba="0.470126 0.661547 0.742536 1"/>
                </material>
            </visual>
            <collision>
                <origin xyz="0.192899 1.61439e-05 -0.0214358" rpy="-1.5794 0.623336 -1.23434"/>
                <geometry>
                    <mesh filename="package://assets/merged/humerus_link_collision.stl"/>
                </geometry>
            </collision>
        </link>
        <!-- Link flat_pattern_of_humerus_link -->
        <link name="flat_pattern_of_humerus_link">
            <inertial>
                <origin xyz="0.0461837 -0.111635 0.0450797" rpy="0 0 0"/>
                <mass value="2.41904"/>
                <inertia ixx="0.0549307" ixy="0.0238789" ixz="-1.1312e-05" iyy="0.0212463" iyz="1.93753e-05" izz="0.064383"/>
            </inertial>
            <!-- Part flat_pattern_of_humerus_link_parts -->
            <visual>
                <origin xyz="0.0461837 -0.111635 0.0450797" rpy="-1.5794 0.623336 1.90726"/>
                <geometry>
                    <mesh filename="package://assets/merged/flat_pattern_of_humerus_link_visual.stl"/>
                </geometry>
                <material name="flat_pattern_of_humerus_link_parts_material">
                    <color rgba="0.358759 0.586672 0.658794 1"/>
                </material>
            </visual>
            <collision>
                <origin xyz="0.0461837 -0.111635 0.0450797" rpy="-1.5794 0.623336 1.90726"/>
                <geometry>
                    <mesh filename="package://assets/merged/flat_pattern_of_humerus_link_collision.stl"/>
                </geometry>
            </collision>
        </link>
        <!-- Link wirst_body -->
        <link name="wirst_body">
            <inertial>
                <origin xyz="1.74216e-05 -0.0133229 -0.0449775" rpy="0 0 0"/>
                <mass value="0.114952"/>
                <inertia ixx="0.000141143" ixy="-3.67177e-10" ixz="8.43247e-07" iyy="0.000208967" iyz="4.47572e-13" izz="9.77212e-05"/>
            </inertial>
            <!-- Part wirst_body_parts -->
            <visual>
                <origin xyz="1.74216e-05 -0.0133229 -0.0449775" rpy="-1.5794 0.623336 1.87508"/>
                <geometry>
                    <mesh filename="package://assets/merged/wirst_body_visual.stl"/>
                </geometry>
                <material name="wirst_body_parts_material">
                    <color rgba="0.0745098 0.678431 0.972549 1"/>
                </material>
            </visual>
            <collision>
                <origin xyz="1.74216e-05 -0.0133229 -0.0449775" rpy="-1.5794 0.623336 1.87508"/>
                <geometry>
                    <mesh filename="package://assets/merged/wirst_body_collision.stl"/>
                </geometry>
            </collision>
        </link>
        <!-- Link wrist_link -->
        <link name="wrist_link">
            <inertial>
                <origin xyz="-1.636e-17 -6.74869e-18 -0.00183593" rpy="0 0 0"/>
                <mass value="0.0230672"/>
                <inertia ixx="6.54736e-06" ixy="1.482e-22" ixz="1.20262e-21" iyy="6.54736e-06" iyz="-9.13762e-22" izz="1.27521e-05"/>
            </inertial>
            <!-- Part wrist_link_parts -->
            <visual>
                <origin xyz="0 6.93889e-18 -0.00183593" rpy="-2.07296 -0.886139 2.06643"/>
                <geometry>
                    <mesh filename="package://assets/merged/wrist_link_visual.stl"/>
                </geometry>
                <material name="wrist_link_parts_material">
                    <color rgba="0.972549 0.529412 0.00392157 1"/>
                </material>
            </visual>
            <collision>
                <origin xyz="0 6.93889e-18 -0.00183593" rpy="-2.07296 -0.886139 2.06643"/>
                <geometry>
                    <mesh filename="package://assets/merged/wrist_link_collision.stl"/>
                </geometry>
            </collision>
        </link>
        <!-- Joint from wirst_body to wrist_link -->
        <joint name="wrist_roll" type="revolute">
            <origin xyz="-5.55112e-17 -0.0314483 -0.0449775" rpy="-1.5708 -0.100784 4.27299e-14"/>
            <parent link="wirst_body"/>
            <child link="wrist_link"/>
            <axis xyz="0 0 1"/>
            <limit effort="10" velocity="10" lower="-3.141592653589793" upper="3.141592653589793"/>
        </joint>
        <!-- Joint from flat_pattern_of_humerus_link to wirst_body -->
        <joint name="wrist_pitch" type="revolute">
            <origin xyz="0.168411 -0.355861 0.0899558" rpy="5.38276e-15 -3.06298e-16 0.0321741"/>
            <parent link="flat_pattern_of_humerus_link"/>
            <child link="wirst_body"/>
            <axis xyz="0 0 1"/>
            <limit effort="10" velocity="10" lower="-1.16095" upper="1.98064"/>
        </joint>
        <!-- Joint from humerus_link to flat_pattern_of_humerus_link -->
        <joint name="elbow_pitch" type="revolute">
            <origin xyz="0.4572 0.031582 -0.067374" rpy="-7.74298e-17 1.17778e-15 -3.14159"/>
            <parent link="humerus_link"/>
            <child link="flat_pattern_of_humerus_link"/>
            <axis xyz="0 0 1"/>
            <limit effort="10" velocity="10" lower="-1.05288" upper="0.517911"/>
        </joint>
        <!-- Joint from base_platter to humerus_link -->
        <joint name="base_pitch" type="revolute">
            <origin xyz="-0.0204961 7.17742e-17 -0.0851182" rpy="-1.5708 1.2144 1.5708"/>
            <parent link="base_platter"/>
            <child link="humerus_link"/>
            <axis xyz="0 0 1"/>
            <limit effort="10" velocity="10" lower="-1.2144" upper="1.9272"/>
        </joint>
        <!-- Joint from base_link to base_platter -->
        <joint name="base_yaw" type="revolute">
            <origin xyz="0.000390865 0.000967073 0.0809889" rpy="3.12667 -0.00698374 0.947443"/>
            <parent link="base_link"/>
            <child link="base_platter"/>
            <axis xyz="0 0 1"/>
            <limit effort="10" velocity="10" lower="-3.141592653589793" upper="3.141592653589793"/>
        </joint>



    </xacro:macro>

</robot>
